[2020-02-10 22:47:42 +0000] [31880] [INFO] Starting gunicorn 20.0.4
[2020-02-10 22:47:42 +0000] [31880] [ERROR] Connection in use: ('127.0.0.1', 8000)
[2020-02-10 22:47:42 +0000] [31880] [ERROR] Retrying in 1 second.
[2020-02-10 22:47:44 +0000] [31880] [ERROR] Connection in use: ('127.0.0.1', 8000)
[2020-02-10 22:47:44 +0000] [31880] [ERROR] Retrying in 1 second.
[2020-02-10 22:47:45 +0000] [31880] [ERROR] Connection in use: ('127.0.0.1', 8000)
[2020-02-10 22:47:45 +0000] [31880] [ERROR] Retrying in 1 second.
[2020-02-10 22:47:46 +0000] [31880] [ERROR] Connection in use: ('127.0.0.1', 8000)
[2020-02-10 22:47:46 +0000] [31880] [ERROR] Retrying in 1 second.
[2020-02-10 22:47:47 +0000] [31880] [ERROR] Connection in use: ('127.0.0.1', 8000)
[2020-02-10 22:47:47 +0000] [31880] [ERROR] Retrying in 1 second.
[2020-02-10 22:47:48 +0000] [31880] [ERROR] Can't connect to ('127.0.0.1', 8000)
[2020-02-10 22:47:48 +0000] [31885] [INFO] Starting gunicorn 20.0.4
[2020-02-10 22:47:48 +0000] [31885] [ERROR] Connection in use: ('127.0.0.1', 8000)
[2020-02-10 22:47:48 +0000] [31885] [ERROR] Retrying in 1 second.
[2020-02-10 22:47:49 +0000] [31885] [ERROR] Connection in use: ('127.0.0.1', 8000)
[2020-02-10 22:47:49 +0000] [31885] [ERROR] Retrying in 1 second.
[2020-02-10 22:47:50 +0000] [31885] [ERROR] Connection in use: ('127.0.0.1', 8000)
[2020-02-10 22:47:50 +0000] [31885] [ERROR] Retrying in 1 second.
[2020-02-10 22:47:51 +0000] [31885] [ERROR] Connection in use: ('127.0.0.1', 8000)
[2020-02-10 22:47:51 +0000] [31885] [ERROR] Retrying in 1 second.
[2020-02-10 22:47:52 +0000] [31885] [ERROR] Connection in use: ('127.0.0.1', 8000)
[2020-02-10 22:47:52 +0000] [31885] [ERROR] Retrying in 1 second.
[2020-02-10 22:47:53 +0000] [31885] [ERROR] Can't connect to ('127.0.0.1', 8000)
[2020-02-10 22:47:54 +0000] [31888] [INFO] Starting gunicorn 20.0.4
[2020-02-10 22:47:54 +0000] [31888] [ERROR] Connection in use: ('127.0.0.1', 8000)
[2020-02-10 22:47:54 +0000] [31888] [ERROR] Retrying in 1 second.
[2020-02-10 22:47:55 +0000] [31888] [ERROR] Connection in use: ('127.0.0.1', 8000)
[2020-02-10 22:47:55 +0000] [31888] [ERROR] Retrying in 1 second.
[2020-02-10 22:47:56 +0000] [31888] [ERROR] Connection in use: ('127.0.0.1', 8000)
[2020-02-10 22:47:56 +0000] [31888] [ERROR] Retrying in 1 second.
[2020-02-10 22:47:57 +0000] [31888] [ERROR] Connection in use: ('127.0.0.1', 8000)
[2020-02-10 22:47:57 +0000] [31888] [ERROR] Retrying in 1 second.
[2020-02-10 22:47:58 +0000] [31888] [ERROR] Connection in use: ('127.0.0.1', 8000)
[2020-02-10 22:47:58 +0000] [31888] [ERROR] Retrying in 1 second.
[2020-02-10 22:47:59 +0000] [31888] [ERROR] Can't connect to ('127.0.0.1', 8000)
[2020-02-10 22:48:01 +0000] [31893] [INFO] Starting gunicorn 20.0.4
[2020-02-10 22:48:01 +0000] [31893] [ERROR] Connection in use: ('127.0.0.1', 8000)
[2020-02-10 22:48:01 +0000] [31893] [ERROR] Retrying in 1 second.
[2020-02-10 22:48:02 +0000] [31893] [ERROR] Connection in use: ('127.0.0.1', 8000)
[2020-02-10 22:48:02 +0000] [31893] [ERROR] Retrying in 1 second.
[2020-02-10 22:48:03 +0000] [31893] [ERROR] Connection in use: ('127.0.0.1', 8000)
[2020-02-10 22:48:03 +0000] [31893] [ERROR] Retrying in 1 second.
[2020-02-10 22:48:04 +0000] [31893] [ERROR] Connection in use: ('127.0.0.1', 8000)
[2020-02-10 22:48:04 +0000] [31893] [ERROR] Retrying in 1 second.
[2020-02-10 22:48:05 +0000] [31893] [ERROR] Connection in use: ('127.0.0.1', 8000)
[2020-02-10 22:48:05 +0000] [31893] [ERROR] Retrying in 1 second.
[2020-02-10 22:48:06 +0000] [31893] [ERROR] Can't connect to ('127.0.0.1', 8000)
[2020-02-10 22:48:06 +0000] [31900] [INFO] Starting gunicorn 20.0.4
[2020-02-10 22:48:06 +0000] [31900] [ERROR] Connection in use: ('127.0.0.1', 8000)
[2020-02-10 22:48:06 +0000] [31900] [ERROR] Retrying in 1 second.
[2020-02-10 22:48:07 +0000] [31900] [ERROR] Connection in use: ('127.0.0.1', 8000)
[2020-02-10 22:48:07 +0000] [31900] [ERROR] Retrying in 1 second.
[2020-02-10 22:48:08 +0000] [31900] [ERROR] Connection in use: ('127.0.0.1', 8000)
[2020-02-10 22:48:08 +0000] [31900] [ERROR] Retrying in 1 second.
[2020-02-10 22:48:09 +0000] [31900] [ERROR] Connection in use: ('127.0.0.1', 8000)
[2020-02-10 22:48:09 +0000] [31900] [ERROR] Retrying in 1 second.
[2020-02-10 22:48:10 +0000] [31900] [ERROR] Connection in use: ('127.0.0.1', 8000)
[2020-02-10 22:48:10 +0000] [31900] [ERROR] Retrying in 1 second.
[2020-02-10 22:48:11 +0000] [31900] [ERROR] Can't connect to ('127.0.0.1', 8000)
[2020-02-10 22:48:12 +0000] [31903] [INFO] Starting gunicorn 20.0.4
[2020-02-10 22:48:12 +0000] [31903] [ERROR] Connection in use: ('127.0.0.1', 8000)
[2020-02-10 22:48:12 +0000] [31903] [ERROR] Retrying in 1 second.
[2020-02-10 22:48:13 +0000] [31903] [ERROR] Connection in use: ('127.0.0.1', 8000)
[2020-02-10 22:48:13 +0000] [31903] [ERROR] Retrying in 1 second.
[2020-02-10 22:48:14 +0000] [31903] [ERROR] Connection in use: ('127.0.0.1', 8000)
[2020-02-10 22:48:14 +0000] [31903] [ERROR] Retrying in 1 second.
[2020-02-10 22:48:15 +0000] [31903] [ERROR] Connection in use: ('127.0.0.1', 8000)
[2020-02-10 22:48:15 +0000] [31903] [ERROR] Retrying in 1 second.
[2020-02-10 22:48:16 +0000] [31903] [ERROR] Connection in use: ('127.0.0.1', 8000)
[2020-02-10 22:48:16 +0000] [31903] [ERROR] Retrying in 1 second.
[2020-02-10 22:48:17 +0000] [31903] [ERROR] Can't connect to ('127.0.0.1', 8000)
[2020-02-10 22:48:19 +0000] [31906] [INFO] Starting gunicorn 20.0.4
[2020-02-10 22:48:19 +0000] [31906] [ERROR] Connection in use: ('127.0.0.1', 8000)
[2020-02-10 22:48:19 +0000] [31906] [ERROR] Retrying in 1 second.
[2020-02-10 22:48:20 +0000] [31906] [ERROR] Connection in use: ('127.0.0.1', 8000)
[2020-02-10 22:48:20 +0000] [31906] [ERROR] Retrying in 1 second.
[2020-02-10 22:48:21 +0000] [31906] [ERROR] Connection in use: ('127.0.0.1', 8000)
[2020-02-10 22:48:21 +0000] [31906] [ERROR] Retrying in 1 second.
[2020-02-10 22:48:22 +0000] [31906] [ERROR] Connection in use: ('127.0.0.1', 8000)
[2020-02-10 22:48:22 +0000] [31906] [ERROR] Retrying in 1 second.
[2020-02-10 22:48:23 +0000] [31906] [ERROR] Connection in use: ('127.0.0.1', 8000)
[2020-02-10 22:48:23 +0000] [31906] [ERROR] Retrying in 1 second.
[2020-02-10 22:48:24 +0000] [31906] [ERROR] Can't connect to ('127.0.0.1', 8000)
[2020-02-10 22:48:25 +0000] [31909] [INFO] Starting gunicorn 20.0.4
[2020-02-10 22:48:25 +0000] [31909] [ERROR] Connection in use: ('127.0.0.1', 8000)
[2020-02-10 22:48:25 +0000] [31909] [ERROR] Retrying in 1 second.
[2020-02-10 22:48:26 +0000] [31909] [ERROR] Connection in use: ('127.0.0.1', 8000)
[2020-02-10 22:48:26 +0000] [31909] [ERROR] Retrying in 1 second.
[2020-02-10 22:48:27 +0000] [31909] [ERROR] Connection in use: ('127.0.0.1', 8000)
[2020-02-10 22:48:27 +0000] [31909] [ERROR] Retrying in 1 second.
[2020-02-10 22:48:28 +0000] [31909] [ERROR] Connection in use: ('127.0.0.1', 8000)
[2020-02-10 22:48:28 +0000] [31909] [ERROR] Retrying in 1 second.
[2020-02-10 22:48:29 +0000] [31909] [ERROR] Connection in use: ('127.0.0.1', 8000)
[2020-02-10 22:48:29 +0000] [31909] [ERROR] Retrying in 1 second.
[2020-02-10 22:48:30 +0000] [31909] [ERROR] Can't connect to ('127.0.0.1', 8000)
[2020-02-10 22:48:31 +0000] [31926] [INFO] Starting gunicorn 20.0.4
[2020-02-10 22:48:31 +0000] [31926] [ERROR] Connection in use: ('127.0.0.1', 8000)
[2020-02-10 22:48:31 +0000] [31926] [ERROR] Retrying in 1 second.
[2020-02-10 22:48:32 +0000] [31926] [ERROR] Connection in use: ('127.0.0.1', 8000)
[2020-02-10 22:48:32 +0000] [31926] [ERROR] Retrying in 1 second.
[2020-02-10 22:48:33 +0000] [31926] [ERROR] Connection in use: ('127.0.0.1', 8000)
[2020-02-10 22:48:33 +0000] [31926] [ERROR] Retrying in 1 second.
[2020-02-10 22:48:34 +0000] [31926] [ERROR] Connection in use: ('127.0.0.1', 8000)
[2020-02-10 22:48:34 +0000] [31926] [ERROR] Retrying in 1 second.
[2020-02-10 22:48:35 +0000] [31926] [ERROR] Connection in use: ('127.0.0.1', 8000)
[2020-02-10 22:48:35 +0000] [31926] [ERROR] Retrying in 1 second.
[2020-02-10 22:48:36 +0000] [31926] [ERROR] Can't connect to ('127.0.0.1', 8000)
[2020-02-10 22:48:37 +0000] [31929] [INFO] Starting gunicorn 20.0.4
[2020-02-10 22:48:37 +0000] [31929] [ERROR] Connection in use: ('127.0.0.1', 8000)
[2020-02-10 22:48:37 +0000] [31929] [ERROR] Retrying in 1 second.
[2020-02-10 22:48:38 +0000] [31929] [ERROR] Connection in use: ('127.0.0.1', 8000)
[2020-02-10 22:48:38 +0000] [31929] [ERROR] Retrying in 1 second.
[2020-02-10 22:48:39 +0000] [31929] [ERROR] Connection in use: ('127.0.0.1', 8000)
[2020-02-10 22:48:39 +0000] [31929] [ERROR] Retrying in 1 second.
[2020-02-10 22:48:40 +0000] [31929] [ERROR] Connection in use: ('127.0.0.1', 8000)
[2020-02-10 22:48:40 +0000] [31929] [ERROR] Retrying in 1 second.
[2020-02-10 22:48:41 +0000] [31929] [ERROR] Connection in use: ('127.0.0.1', 8000)
[2020-02-10 22:48:41 +0000] [31929] [ERROR] Retrying in 1 second.
[2020-02-10 22:48:42 +0000] [31929] [ERROR] Can't connect to ('127.0.0.1', 8000)
[2020-02-10 22:48:43 +0000] [31932] [INFO] Starting gunicorn 20.0.4
[2020-02-10 22:48:43 +0000] [31932] [ERROR] Connection in use: ('127.0.0.1', 8000)
[2020-02-10 22:48:43 +0000] [31932] [ERROR] Retrying in 1 second.
[2020-02-10 22:48:44 +0000] [31932] [ERROR] Connection in use: ('127.0.0.1', 8000)
[2020-02-10 22:48:44 +0000] [31932] [ERROR] Retrying in 1 second.
[2020-02-10 22:48:45 +0000] [31932] [ERROR] Connection in use: ('127.0.0.1', 8000)
[2020-02-10 22:48:45 +0000] [31932] [ERROR] Retrying in 1 second.
[2020-02-10 22:48:46 +0000] [31932] [ERROR] Connection in use: ('127.0.0.1', 8000)
[2020-02-10 22:48:46 +0000] [31932] [ERROR] Retrying in 1 second.
[2020-02-10 22:48:47 +0000] [31932] [ERROR] Connection in use: ('127.0.0.1', 8000)
[2020-02-10 22:48:47 +0000] [31932] [ERROR] Retrying in 1 second.
[2020-02-10 22:48:48 +0000] [31932] [ERROR] Can't connect to ('127.0.0.1', 8000)
[2020-02-10 22:48:50 +0000] [31935] [INFO] Starting gunicorn 20.0.4
[2020-02-10 22:48:50 +0000] [31935] [ERROR] Connection in use: ('127.0.0.1', 8000)
[2020-02-10 22:48:50 +0000] [31935] [ERROR] Retrying in 1 second.
[2020-02-10 22:48:51 +0000] [31935] [ERROR] Connection in use: ('127.0.0.1', 8000)
[2020-02-10 22:48:51 +0000] [31935] [ERROR] Retrying in 1 second.
[2020-02-10 22:48:52 +0000] [31935] [ERROR] Connection in use: ('127.0.0.1', 8000)
[2020-02-10 22:48:52 +0000] [31935] [ERROR] Retrying in 1 second.
[2020-02-10 22:48:53 +0000] [31935] [ERROR] Connection in use: ('127.0.0.1', 8000)
[2020-02-10 22:48:53 +0000] [31935] [ERROR] Retrying in 1 second.
[2020-02-10 22:48:54 +0000] [31935] [ERROR] Connection in use: ('127.0.0.1', 8000)
[2020-02-10 22:48:54 +0000] [31935] [ERROR] Retrying in 1 second.
[2020-02-10 22:48:55 +0000] [31935] [ERROR] Can't connect to ('127.0.0.1', 8000)
[2020-02-10 22:48:56 +0000] [31938] [INFO] Starting gunicorn 20.0.4
[2020-02-10 22:48:56 +0000] [31938] [ERROR] Connection in use: ('127.0.0.1', 8000)
[2020-02-10 22:48:56 +0000] [31938] [ERROR] Retrying in 1 second.
[2020-02-10 22:48:57 +0000] [31938] [ERROR] Connection in use: ('127.0.0.1', 8000)
[2020-02-10 22:48:57 +0000] [31938] [ERROR] Retrying in 1 second.
[2020-02-10 22:48:58 +0000] [31938] [ERROR] Connection in use: ('127.0.0.1', 8000)
[2020-02-10 22:48:58 +0000] [31938] [ERROR] Retrying in 1 second.
[2020-02-10 22:48:59 +0000] [31938] [ERROR] Connection in use: ('127.0.0.1', 8000)
[2020-02-10 22:48:59 +0000] [31938] [ERROR] Retrying in 1 second.
[2020-02-10 22:49:00 +0000] [31938] [ERROR] Connection in use: ('127.0.0.1', 8000)
[2020-02-10 22:49:00 +0000] [31938] [ERROR] Retrying in 1 second.
[2020-02-10 22:49:01 +0000] [31938] [ERROR] Can't connect to ('127.0.0.1', 8000)
[2020-02-10 22:49:02 +0000] [31941] [INFO] Starting gunicorn 20.0.4
[2020-02-10 22:49:02 +0000] [31941] [ERROR] Connection in use: ('127.0.0.1', 8000)
[2020-02-10 22:49:02 +0000] [31941] [ERROR] Retrying in 1 second.
[2020-02-10 22:49:03 +0000] [31941] [ERROR] Connection in use: ('127.0.0.1', 8000)
[2020-02-10 22:49:03 +0000] [31941] [ERROR] Retrying in 1 second.
[2020-02-10 22:49:04 +0000] [31941] [ERROR] Connection in use: ('127.0.0.1', 8000)
[2020-02-10 22:49:04 +0000] [31941] [ERROR] Retrying in 1 second.
[2020-02-10 22:49:05 +0000] [31941] [ERROR] Connection in use: ('127.0.0.1', 8000)
[2020-02-10 22:49:05 +0000] [31941] [ERROR] Retrying in 1 second.
[2020-02-10 22:49:06 +0000] [31941] [ERROR] Connection in use: ('127.0.0.1', 8000)
[2020-02-10 22:49:06 +0000] [31941] [ERROR] Retrying in 1 second.
[2020-02-10 22:49:07 +0000] [31941] [ERROR] Can't connect to ('127.0.0.1', 8000)
[2020-02-10 22:49:08 +0000] [31944] [INFO] Starting gunicorn 20.0.4
[2020-02-10 22:49:08 +0000] [31944] [ERROR] Connection in use: ('127.0.0.1', 8000)
[2020-02-10 22:49:08 +0000] [31944] [ERROR] Retrying in 1 second.
[2020-02-10 22:49:09 +0000] [31944] [ERROR] Connection in use: ('127.0.0.1', 8000)
[2020-02-10 22:49:09 +0000] [31944] [ERROR] Retrying in 1 second.
[2020-02-10 22:49:10 +0000] [31944] [ERROR] Connection in use: ('127.0.0.1', 8000)
[2020-02-10 22:49:10 +0000] [31944] [ERROR] Retrying in 1 second.
[2020-02-10 22:49:11 +0000] [31944] [ERROR] Connection in use: ('127.0.0.1', 8000)
[2020-02-10 22:49:11 +0000] [31944] [ERROR] Retrying in 1 second.
[2020-02-10 22:49:12 +0000] [31944] [ERROR] Connection in use: ('127.0.0.1', 8000)
[2020-02-10 22:49:12 +0000] [31944] [ERROR] Retrying in 1 second.
[2020-02-10 22:49:13 +0000] [31944] [ERROR] Can't connect to ('127.0.0.1', 8000)
[2020-02-10 22:49:14 +0000] [31948] [INFO] Starting gunicorn 20.0.4
[2020-02-10 22:49:14 +0000] [31948] [ERROR] Connection in use: ('127.0.0.1', 8000)
[2020-02-10 22:49:14 +0000] [31948] [ERROR] Retrying in 1 second.
[2020-02-10 22:49:15 +0000] [31948] [ERROR] Connection in use: ('127.0.0.1', 8000)
[2020-02-10 22:49:15 +0000] [31948] [ERROR] Retrying in 1 second.
[2020-02-10 22:49:16 +0000] [31948] [ERROR] Connection in use: ('127.0.0.1', 8000)
[2020-02-10 22:49:16 +0000] [31948] [ERROR] Retrying in 1 second.
[2020-02-10 22:49:17 +0000] [31948] [ERROR] Connection in use: ('127.0.0.1', 8000)
[2020-02-10 22:49:17 +0000] [31948] [ERROR] Retrying in 1 second.
[2020-02-10 22:49:18 +0000] [31948] [ERROR] Connection in use: ('127.0.0.1', 8000)
[2020-02-10 22:49:18 +0000] [31948] [ERROR] Retrying in 1 second.
[2020-02-10 22:49:19 +0000] [31948] [ERROR] Can't connect to ('127.0.0.1', 8000)
[2020-02-10 22:49:21 +0000] [31951] [INFO] Starting gunicorn 20.0.4
[2020-02-10 22:49:21 +0000] [31951] [ERROR] Connection in use: ('127.0.0.1', 8000)
[2020-02-10 22:49:21 +0000] [31951] [ERROR] Retrying in 1 second.
[2020-02-10 22:49:22 +0000] [31951] [ERROR] Connection in use: ('127.0.0.1', 8000)
[2020-02-10 22:49:22 +0000] [31951] [ERROR] Retrying in 1 second.
[2020-02-10 22:49:23 +0000] [31951] [ERROR] Connection in use: ('127.0.0.1', 8000)
[2020-02-10 22:49:23 +0000] [31951] [ERROR] Retrying in 1 second.
[2020-02-10 22:49:24 +0000] [31951] [ERROR] Connection in use: ('127.0.0.1', 8000)
[2020-02-10 22:49:24 +0000] [31951] [ERROR] Retrying in 1 second.
[2020-02-10 22:49:25 +0000] [31951] [ERROR] Connection in use: ('127.0.0.1', 8000)
[2020-02-10 22:49:25 +0000] [31951] [ERROR] Retrying in 1 second.
[2020-02-10 22:49:26 +0000] [31951] [ERROR] Can't connect to ('127.0.0.1', 8000)
[2020-02-10 22:49:27 +0000] [31954] [INFO] Starting gunicorn 20.0.4
[2020-02-10 22:49:27 +0000] [31954] [ERROR] Connection in use: ('127.0.0.1', 8000)
[2020-02-10 22:49:27 +0000] [31954] [ERROR] Retrying in 1 second.
[2020-02-10 22:49:28 +0000] [31954] [ERROR] Connection in use: ('127.0.0.1', 8000)
[2020-02-10 22:49:28 +0000] [31954] [ERROR] Retrying in 1 second.
[2020-02-10 22:49:29 +0000] [31954] [ERROR] Connection in use: ('127.0.0.1', 8000)
[2020-02-10 22:49:29 +0000] [31954] [ERROR] Retrying in 1 second.
[2020-02-10 22:49:30 +0000] [31954] [ERROR] Connection in use: ('127.0.0.1', 8000)
[2020-02-10 22:49:30 +0000] [31954] [ERROR] Retrying in 1 second.
[2020-02-10 22:49:31 +0000] [31954] [ERROR] Connection in use: ('127.0.0.1', 8000)
[2020-02-10 22:49:31 +0000] [31954] [ERROR] Retrying in 1 second.
[2020-02-10 22:49:32 +0000] [31954] [ERROR] Can't connect to ('127.0.0.1', 8000)
[2020-02-10 22:49:33 +0000] [31957] [INFO] Starting gunicorn 20.0.4
[2020-02-10 22:49:33 +0000] [31957] [ERROR] Connection in use: ('127.0.0.1', 8000)
[2020-02-10 22:49:33 +0000] [31957] [ERROR] Retrying in 1 second.
[2020-02-10 22:49:34 +0000] [31957] [ERROR] Connection in use: ('127.0.0.1', 8000)
[2020-02-10 22:49:34 +0000] [31957] [ERROR] Retrying in 1 second.
[2020-02-10 22:49:35 +0000] [31957] [INFO] Listening at: http://127.0.0.1:8000 (31957)
[2020-02-10 22:49:35 +0000] [31957] [INFO] Using worker: sync
[2020-02-10 22:49:35 +0000] [31960] [INFO] Booting worker with pid: 31960
[2020-02-10 22:49:35 +0000] [31961] [INFO] Booting worker with pid: 31961
[2020-02-10 22:49:35 +0000] [31962] [INFO] Booting worker with pid: 31962
[2020-02-10 22:51:23 +0000] [31957] [INFO] Handling signal: term
[2020-02-10 22:51:23 +0000] [31960] [INFO] Worker exiting (pid: 31960)
[2020-02-10 22:51:23 +0000] [31961] [INFO] Worker exiting (pid: 31961)
[2020-02-10 22:51:23 +0000] [31962] [INFO] Worker exiting (pid: 31962)
[2020-02-10 22:51:23 +0000] [31957] [INFO] Shutting down: Master
[2020-02-10 22:51:23 +0000] [32002] [INFO] Starting gunicorn 20.0.4
[2020-02-10 22:51:23 +0000] [32002] [INFO] Listening at: http://127.0.0.1:8000 (32002)
[2020-02-10 22:51:23 +0000] [32002] [INFO] Using worker: sync
[2020-02-10 22:51:23 +0000] [32005] [INFO] Booting worker with pid: 32005
[2020-02-10 22:51:23 +0000] [32006] [INFO] Booting worker with pid: 32006
[2020-02-10 22:51:23 +0000] [32007] [INFO] Booting worker with pid: 32007
[2020-02-11 03:05:57 +0000] [32002] [INFO] Handling signal: term
[2020-02-11 03:05:57 +0000] [32005] [INFO] Worker exiting (pid: 32005)
[2020-02-11 03:05:57 +0000] [32006] [INFO] Worker exiting (pid: 32006)
[2020-02-11 03:05:57 +0000] [32007] [INFO] Worker exiting (pid: 32007)
[2020-02-11 03:05:58 +0000] [32002] [INFO] Shutting down: Master
[2020-02-11 03:05:58 +0000] [2894] [INFO] Starting gunicorn 20.0.4
[2020-02-11 03:05:58 +0000] [2894] [INFO] Listening at: http://127.0.0.1:8000 (2894)
[2020-02-11 03:05:58 +0000] [2894] [INFO] Using worker: sync
[2020-02-11 03:05:58 +0000] [2897] [INFO] Booting worker with pid: 2897
[2020-02-11 03:05:58 +0000] [2897] [ERROR] Exception in worker process
Traceback (most recent call last):
  File "/home/javirodrigues/miniconda3/lib/python3.7/site-packages/gunicorn/arbiter.py", line 583, in spawn_worker
    worker.init_process()
  File "/home/javirodrigues/miniconda3/lib/python3.7/site-packages/gunicorn/workers/base.py", line 119, in init_process
    self.load_wsgi()
  File "/home/javirodrigues/miniconda3/lib/python3.7/site-packages/gunicorn/workers/base.py", line 144, in load_wsgi
    self.wsgi = self.app.wsgi()
  File "/home/javirodrigues/miniconda3/lib/python3.7/site-packages/gunicorn/app/base.py", line 67, in wsgi
    self.callable = self.load()
  File "/home/javirodrigues/miniconda3/lib/python3.7/site-packages/gunicorn/app/wsgiapp.py", line 49, in load
    return self.load_wsgiapp()
  File "/home/javirodrigues/miniconda3/lib/python3.7/site-packages/gunicorn/app/wsgiapp.py", line 39, in load_wsgiapp
    return util.import_app(self.app_uri)
  File "/home/javirodrigues/miniconda3/lib/python3.7/site-packages/gunicorn/util.py", line 358, in import_app
    mod = importlib.import_module(module)
  File "/home/javirodrigues/miniconda3/lib/python3.7/importlib/__init__.py", line 127, in import_module
    return _bootstrap._gcd_import(name[level:], package, level)
  File "<frozen importlib._bootstrap>", line 1006, in _gcd_import
  File "<frozen importlib._bootstrap>", line 983, in _find_and_load
  File "<frozen importlib._bootstrap>", line 967, in _find_and_load_unlocked
  File "<frozen importlib._bootstrap>", line 677, in _load_unlocked
  File "<frozen importlib._bootstrap_external>", line 724, in exec_module
  File "<frozen importlib._bootstrap_external>", line 860, in get_code
  File "<frozen importlib._bootstrap_external>", line 791, in source_to_code
  File "<frozen importlib._bootstrap>", line 219, in _call_with_frames_removed
  File "/home/javirodrigues/INFO8000/Assignment3/test_app.py", line 31
    @app.route('/read/all', methods=['GET']))
                                            ^
SyntaxError: invalid syntax
[2020-02-11 03:05:58 +0000] [2897] [INFO] Worker exiting (pid: 2897)
[2020-02-11 03:05:58 +0000] [2894] [INFO] Shutting down: Master
[2020-02-11 03:05:58 +0000] [2894] [INFO] Reason: Worker failed to boot.
[2020-02-11 03:05:59 +0000] [2898] [INFO] Starting gunicorn 20.0.4
[2020-02-11 03:05:59 +0000] [2898] [INFO] Listening at: http://127.0.0.1:8000 (2898)
[2020-02-11 03:05:59 +0000] [2898] [INFO] Using worker: sync
[2020-02-11 03:05:59 +0000] [2901] [INFO] Booting worker with pid: 2901
[2020-02-11 03:05:59 +0000] [2901] [ERROR] Exception in worker process
Traceback (most recent call last):
  File "/home/javirodrigues/miniconda3/lib/python3.7/site-packages/gunicorn/arbiter.py", line 583, in spawn_worker
    worker.init_process()
  File "/home/javirodrigues/miniconda3/lib/python3.7/site-packages/gunicorn/workers/base.py", line 119, in init_process
    self.load_wsgi()
  File "/home/javirodrigues/miniconda3/lib/python3.7/site-packages/gunicorn/workers/base.py", line 144, in load_wsgi
    self.wsgi = self.app.wsgi()
  File "/home/javirodrigues/miniconda3/lib/python3.7/site-packages/gunicorn/app/base.py", line 67, in wsgi
    self.callable = self.load()
  File "/home/javirodrigues/miniconda3/lib/python3.7/site-packages/gunicorn/app/wsgiapp.py", line 49, in load
    return self.load_wsgiapp()
  File "/home/javirodrigues/miniconda3/lib/python3.7/site-packages/gunicorn/app/wsgiapp.py", line 39, in load_wsgiapp
    return util.import_app(self.app_uri)
  File "/home/javirodrigues/miniconda3/lib/python3.7/site-packages/gunicorn/util.py", line 358, in import_app
    mod = importlib.import_module(module)
  File "/home/javirodrigues/miniconda3/lib/python3.7/importlib/__init__.py", line 127, in import_module
    return _bootstrap._gcd_import(name[level:], package, level)
  File "<frozen importlib._bootstrap>", line 1006, in _gcd_import
  File "<frozen importlib._bootstrap>", line 983, in _find_and_load
  File "<frozen importlib._bootstrap>", line 967, in _find_and_load_unlocked
  File "<frozen importlib._bootstrap>", line 677, in _load_unlocked
  File "<frozen importlib._bootstrap_external>", line 724, in exec_module
  File "<frozen importlib._bootstrap_external>", line 860, in get_code
  File "<frozen importlib._bootstrap_external>", line 791, in source_to_code
  File "<frozen importlib._bootstrap>", line 219, in _call_with_frames_removed
  File "/home/javirodrigues/INFO8000/Assignment3/test_app.py", line 31
    @app.route('/read/all', methods=['GET']))
                                            ^
SyntaxError: invalid syntax
[2020-02-11 03:05:59 +0000] [2901] [INFO] Worker exiting (pid: 2901)
[2020-02-11 03:05:59 +0000] [2902] [INFO] Booting worker with pid: 2902
[2020-02-11 03:05:59 +0000] [2902] [ERROR] Exception in worker process
Traceback (most recent call last):
  File "/home/javirodrigues/miniconda3/lib/python3.7/site-packages/gunicorn/arbiter.py", line 583, in spawn_worker
    worker.init_process()
  File "/home/javirodrigues/miniconda3/lib/python3.7/site-packages/gunicorn/workers/base.py", line 119, in init_process
    self.load_wsgi()
  File "/home/javirodrigues/miniconda3/lib/python3.7/site-packages/gunicorn/workers/base.py", line 144, in load_wsgi
    self.wsgi = self.app.wsgi()
  File "/home/javirodrigues/miniconda3/lib/python3.7/site-packages/gunicorn/app/base.py", line 67, in wsgi
    self.callable = self.load()
  File "/home/javirodrigues/miniconda3/lib/python3.7/site-packages/gunicorn/app/wsgiapp.py", line 49, in load
    return self.load_wsgiapp()
  File "/home/javirodrigues/miniconda3/lib/python3.7/site-packages/gunicorn/app/wsgiapp.py", line 39, in load_wsgiapp
    return util.import_app(self.app_uri)
  File "/home/javirodrigues/miniconda3/lib/python3.7/site-packages/gunicorn/util.py", line 358, in import_app
    mod = importlib.import_module(module)
  File "/home/javirodrigues/miniconda3/lib/python3.7/importlib/__init__.py", line 127, in import_module
    return _bootstrap._gcd_import(name[level:], package, level)
  File "<frozen importlib._bootstrap>", line 1006, in _gcd_import
  File "<frozen importlib._bootstrap>", line 983, in _find_and_load
  File "<frozen importlib._bootstrap>", line 967, in _find_and_load_unlocked
  File "<frozen importlib._bootstrap>", line 677, in _load_unlocked
  File "<frozen importlib._bootstrap_external>", line 724, in exec_module
  File "<frozen importlib._bootstrap_external>", line 860, in get_code
  File "<frozen importlib._bootstrap_external>", line 791, in source_to_code
  File "<frozen importlib._bootstrap>", line 219, in _call_with_frames_removed
  File "/home/javirodrigues/INFO8000/Assignment3/test_app.py", line 31
    @app.route('/read/all', methods=['GET']))
                                            ^
SyntaxError: invalid syntax
[2020-02-11 03:05:59 +0000] [2902] [INFO] Worker exiting (pid: 2902)
Traceback (most recent call last):
  File "/home/javirodrigues/miniconda3/lib/python3.7/site-packages/gunicorn/arbiter.py", line 202, in run
    self.manage_workers()
  File "/home/javirodrigues/miniconda3/lib/python3.7/site-packages/gunicorn/arbiter.py", line 545, in manage_workers
    self.spawn_workers()
  File "/home/javirodrigues/miniconda3/lib/python3.7/site-packages/gunicorn/arbiter.py", line 617, in spawn_workers
    time.sleep(0.1 * random.random())
  File "/home/javirodrigues/miniconda3/lib/python3.7/site-packages/gunicorn/arbiter.py", line 242, in handle_chld
    self.reap_workers()
  File "/home/javirodrigues/miniconda3/lib/python3.7/site-packages/gunicorn/arbiter.py", line 525, in reap_workers
    raise HaltServer(reason, self.WORKER_BOOT_ERROR)
gunicorn.errors.HaltServer: <HaltServer 'Worker failed to boot.' 3>

During handling of the above exception, another exception occurred:

Traceback (most recent call last):
  File "/home/javirodrigues/miniconda3/bin/gunicorn", line 11, in <module>
    sys.exit(run())
  File "/home/javirodrigues/miniconda3/lib/python3.7/site-packages/gunicorn/app/wsgiapp.py", line 58, in run
    WSGIApplication("%(prog)s [OPTIONS] [APP_MODULE]").run()
  File "/home/javirodrigues/miniconda3/lib/python3.7/site-packages/gunicorn/app/base.py", line 228, in run
    super().run()
  File "/home/javirodrigues/miniconda3/lib/python3.7/site-packages/gunicorn/app/base.py", line 72, in run
    Arbiter(self).run()
  File "/home/javirodrigues/miniconda3/lib/python3.7/site-packages/gunicorn/arbiter.py", line 229, in run
    self.halt(reason=inst.reason, exit_status=inst.exit_status)
  File "/home/javirodrigues/miniconda3/lib/python3.7/site-packages/gunicorn/arbiter.py", line 342, in halt
    self.stop()
  File "/home/javirodrigues/miniconda3/lib/python3.7/site-packages/gunicorn/arbiter.py", line 393, in stop
    time.sleep(0.1)
  File "/home/javirodrigues/miniconda3/lib/python3.7/site-packages/gunicorn/arbiter.py", line 242, in handle_chld
    self.reap_workers()
  File "/home/javirodrigues/miniconda3/lib/python3.7/site-packages/gunicorn/arbiter.py", line 525, in reap_workers
    raise HaltServer(reason, self.WORKER_BOOT_ERROR)
gunicorn.errors.HaltServer: <HaltServer 'Worker failed to boot.' 3>
[2020-02-11 03:06:01 +0000] [2903] [INFO] Starting gunicorn 20.0.4
[2020-02-11 03:06:01 +0000] [2903] [INFO] Listening at: http://127.0.0.1:8000 (2903)
[2020-02-11 03:06:01 +0000] [2903] [INFO] Using worker: sync
[2020-02-11 03:06:01 +0000] [2906] [INFO] Booting worker with pid: 2906
[2020-02-11 03:06:01 +0000] [2906] [ERROR] Exception in worker process
Traceback (most recent call last):
  File "/home/javirodrigues/miniconda3/lib/python3.7/site-packages/gunicorn/arbiter.py", line 583, in spawn_worker
    worker.init_process()
  File "/home/javirodrigues/miniconda3/lib/python3.7/site-packages/gunicorn/workers/base.py", line 119, in init_process
    self.load_wsgi()
  File "/home/javirodrigues/miniconda3/lib/python3.7/site-packages/gunicorn/workers/base.py", line 144, in load_wsgi
    self.wsgi = self.app.wsgi()
  File "/home/javirodrigues/miniconda3/lib/python3.7/site-packages/gunicorn/app/base.py", line 67, in wsgi
    self.callable = self.load()
  File "/home/javirodrigues/miniconda3/lib/python3.7/site-packages/gunicorn/app/wsgiapp.py", line 49, in load
    return self.load_wsgiapp()
  File "/home/javirodrigues/miniconda3/lib/python3.7/site-packages/gunicorn/app/wsgiapp.py", line 39, in load_wsgiapp
    return util.import_app(self.app_uri)
  File "/home/javirodrigues/miniconda3/lib/python3.7/site-packages/gunicorn/util.py", line 358, in import_app
    mod = importlib.import_module(module)
  File "/home/javirodrigues/miniconda3/lib/python3.7/importlib/__init__.py", line 127, in import_module
    return _bootstrap._gcd_import(name[level:], package, level)
  File "<frozen importlib._bootstrap>", line 1006, in _gcd_import
  File "<frozen importlib._bootstrap>", line 983, in _find_and_load
  File "<frozen importlib._bootstrap>", line 967, in _find_and_load_unlocked
  File "<frozen importlib._bootstrap>", line 677, in _load_unlocked
  File "<frozen importlib._bootstrap_external>", line 724, in exec_module
  File "<frozen importlib._bootstrap_external>", line 860, in get_code
  File "<frozen importlib._bootstrap_external>", line 791, in source_to_code
  File "<frozen importlib._bootstrap>", line 219, in _call_with_frames_removed
  File "/home/javirodrigues/INFO8000/Assignment3/test_app.py", line 31
    @app.route('/read/all', methods=['GET']))
                                            ^
SyntaxError: invalid syntax
[2020-02-11 03:06:01 +0000] [2906] [INFO] Worker exiting (pid: 2906)
[2020-02-11 03:06:01 +0000] [2907] [INFO] Booting worker with pid: 2907
[2020-02-11 03:06:01 +0000] [2907] [ERROR] Exception in worker process
Traceback (most recent call last):
  File "/home/javirodrigues/miniconda3/lib/python3.7/site-packages/gunicorn/arbiter.py", line 583, in spawn_worker
    worker.init_process()
  File "/home/javirodrigues/miniconda3/lib/python3.7/site-packages/gunicorn/workers/base.py", line 119, in init_process
    self.load_wsgi()
  File "/home/javirodrigues/miniconda3/lib/python3.7/site-packages/gunicorn/workers/base.py", line 144, in load_wsgi
    self.wsgi = self.app.wsgi()
  File "/home/javirodrigues/miniconda3/lib/python3.7/site-packages/gunicorn/app/base.py", line 67, in wsgi
    self.callable = self.load()
  File "/home/javirodrigues/miniconda3/lib/python3.7/site-packages/gunicorn/app/wsgiapp.py", line 49, in load
    return self.load_wsgiapp()
  File "/home/javirodrigues/miniconda3/lib/python3.7/site-packages/gunicorn/app/wsgiapp.py", line 39, in load_wsgiapp
    return util.import_app(self.app_uri)
  File "/home/javirodrigues/miniconda3/lib/python3.7/site-packages/gunicorn/util.py", line 358, in import_app
    mod = importlib.import_module(module)
  File "/home/javirodrigues/miniconda3/lib/python3.7/importlib/__init__.py", line 127, in import_module
    return _bootstrap._gcd_import(name[level:], package, level)
  File "<frozen importlib._bootstrap>", line 1006, in _gcd_import
  File "<frozen importlib._bootstrap>", line 983, in _find_and_load
  File "<frozen importlib._bootstrap>", line 967, in _find_and_load_unlocked
  File "<frozen importlib._bootstrap>", line 677, in _load_unlocked
  File "<frozen importlib._bootstrap_external>", line 724, in exec_module
  File "<frozen importlib._bootstrap_external>", line 860, in get_code
  File "<frozen importlib._bootstrap_external>", line 791, in source_to_code
  File "<frozen importlib._bootstrap>", line 219, in _call_with_frames_removed
  File "/home/javirodrigues/INFO8000/Assignment3/test_app.py", line 31
    @app.route('/read/all', methods=['GET']))
                                            ^
SyntaxError: invalid syntax
[2020-02-11 03:06:01 +0000] [2907] [INFO] Worker exiting (pid: 2907)
[2020-02-11 03:06:01 +0000] [2908] [INFO] Booting worker with pid: 2908
[2020-02-11 03:06:01 +0000] [2908] [ERROR] Exception in worker process
Traceback (most recent call last):
  File "/home/javirodrigues/miniconda3/lib/python3.7/site-packages/gunicorn/arbiter.py", line 583, in spawn_worker
    worker.init_process()
  File "/home/javirodrigues/miniconda3/lib/python3.7/site-packages/gunicorn/workers/base.py", line 119, in init_process
    self.load_wsgi()
  File "/home/javirodrigues/miniconda3/lib/python3.7/site-packages/gunicorn/workers/base.py", line 144, in load_wsgi
    self.wsgi = self.app.wsgi()
  File "/home/javirodrigues/miniconda3/lib/python3.7/site-packages/gunicorn/app/base.py", line 67, in wsgi
    self.callable = self.load()
  File "/home/javirodrigues/miniconda3/lib/python3.7/site-packages/gunicorn/app/wsgiapp.py", line 49, in load
    return self.load_wsgiapp()
  File "/home/javirodrigues/miniconda3/lib/python3.7/site-packages/gunicorn/app/wsgiapp.py", line 39, in load_wsgiapp
    return util.import_app(self.app_uri)
  File "/home/javirodrigues/miniconda3/lib/python3.7/site-packages/gunicorn/util.py", line 358, in import_app
    mod = importlib.import_module(module)
  File "/home/javirodrigues/miniconda3/lib/python3.7/importlib/__init__.py", line 127, in import_module
    return _bootstrap._gcd_import(name[level:], package, level)
  File "<frozen importlib._bootstrap>", line 1006, in _gcd_import
  File "<frozen importlib._bootstrap>", line 983, in _find_and_load
  File "<frozen importlib._bootstrap>", line 967, in _find_and_load_unlocked
  File "<frozen importlib._bootstrap>", line 677, in _load_unlocked
  File "<frozen importlib._bootstrap_external>", line 724, in exec_module
  File "<frozen importlib._bootstrap_external>", line 860, in get_code
  File "<frozen importlib._bootstrap_external>", line 791, in source_to_code
  File "<frozen importlib._bootstrap>", line 219, in _call_with_frames_removed
  File "/home/javirodrigues/INFO8000/Assignment3/test_app.py", line 31
    @app.route('/read/all', methods=['GET']))
                                            ^
SyntaxError: invalid syntax
[2020-02-11 03:06:02 +0000] [2908] [INFO] Worker exiting (pid: 2908)
[2020-02-11 03:06:02 +0000] [2903] [INFO] Shutting down: Master
[2020-02-11 03:06:02 +0000] [2903] [INFO] Reason: Worker failed to boot.
[2020-02-11 03:06:05 +0000] [2909] [INFO] Starting gunicorn 20.0.4
[2020-02-11 03:06:05 +0000] [2909] [INFO] Listening at: http://127.0.0.1:8000 (2909)
[2020-02-11 03:06:05 +0000] [2909] [INFO] Using worker: sync
[2020-02-11 03:06:05 +0000] [2912] [INFO] Booting worker with pid: 2912
[2020-02-11 03:06:05 +0000] [2912] [ERROR] Exception in worker process
Traceback (most recent call last):
  File "/home/javirodrigues/miniconda3/lib/python3.7/site-packages/gunicorn/arbiter.py", line 583, in spawn_worker
    worker.init_process()
  File "/home/javirodrigues/miniconda3/lib/python3.7/site-packages/gunicorn/workers/base.py", line 119, in init_process
    self.load_wsgi()
  File "/home/javirodrigues/miniconda3/lib/python3.7/site-packages/gunicorn/workers/base.py", line 144, in load_wsgi
    self.wsgi = self.app.wsgi()
  File "/home/javirodrigues/miniconda3/lib/python3.7/site-packages/gunicorn/app/base.py", line 67, in wsgi
    self.callable = self.load()
  File "/home/javirodrigues/miniconda3/lib/python3.7/site-packages/gunicorn/app/wsgiapp.py", line 49, in load
    return self.load_wsgiapp()
  File "/home/javirodrigues/miniconda3/lib/python3.7/site-packages/gunicorn/app/wsgiapp.py", line 39, in load_wsgiapp
    return util.import_app(self.app_uri)
  File "/home/javirodrigues/miniconda3/lib/python3.7/site-packages/gunicorn/util.py", line 358, in import_app
    mod = importlib.import_module(module)
  File "/home/javirodrigues/miniconda3/lib/python3.7/importlib/__init__.py", line 127, in import_module
    return _bootstrap._gcd_import(name[level:], package, level)
  File "<frozen importlib._bootstrap>", line 1006, in _gcd_import
  File "<frozen importlib._bootstrap>", line 983, in _find_and_load
  File "<frozen importlib._bootstrap>", line 967, in _find_and_load_unlocked
  File "<frozen importlib._bootstrap>", line 677, in _load_unlocked
  File "<frozen importlib._bootstrap_external>", line 724, in exec_module
  File "<frozen importlib._bootstrap_external>", line 860, in get_code
  File "<frozen importlib._bootstrap_external>", line 791, in source_to_code
  File "<frozen importlib._bootstrap>", line 219, in _call_with_frames_removed
  File "/home/javirodrigues/INFO8000/Assignment3/test_app.py", line 31
    @app.route('/read/all', methods=['GET']))
                                            ^
SyntaxError: invalid syntax
[2020-02-11 03:06:05 +0000] [2912] [INFO] Worker exiting (pid: 2912)
[2020-02-11 03:06:05 +0000] [2909] [INFO] Shutting down: Master
[2020-02-11 03:06:05 +0000] [2909] [INFO] Reason: Worker failed to boot.
